Workbook

Sheet Panduan
A1: PANDUAN PENGGUNAAN — LKS 2026 Penilaian Juri
A2: BANTUAN ONLINE (GitHub) — klik baris di bawah jika bingung cara pakai:
A3: → Daftar semua panduan juri
A4: → Modul A — Organisasi & manajemen kerja
A5: → Modul B — Jurnal teknis
A6: → Modul C — Perakitan robot
A7: → Modul D — Gerakan dasar
A8: → Modul E — panduan lengkap (WAJIB BACA)
A9: → Log Run Otonom — panduan lengkap (WAJIB BACA)
A10: → Modul E — contoh angka step-by-step
A11: → Undian Kubus — pengacakan posisi
A12: → Rekapitulasi — total & CIS
... A32: Sheet: Panduan | Modul A-E | Undian Kubus | Log Run | Rekapitulasi

Sheet Modul A
A1: MODUL A — Organisasi & Manajemen Kerja (8 poin, Judgement)
A2: Bingung cara nilai Modul A? Buka panduan di GitHub (klik di sini)
A3: Tim No: | C3: Nama Tim: | E3: Kontingen: | G3: Tanggal:
A4: Juri 1: | C4: Juri 2: | E4: Juri 3:
A6: Sub | B6: Kriteria | C6: Max | D6: Juri 1 | E6: Juri 2 | F6: Juri 3 | G6: Rata-rata | H6: Skor Akhir | I6: Selisih | J6: Catatan
A7: A1 | B7: Efisiensi Penjadwalan Kerja | C7: 2 | G7: =IF(COUNT(D7:F7)=0,"",AVERAGE(D7:F7)) | H7: =IF(G7="",0,G7*C7/3) | I7: =IF(COUNT(D7:F7)<2,"",MAX(D7:F7)-MIN(D7:F7))
A8: A2 | B8: Kolaborasi Tim & Manajemen Tugas | C8: 2 | G8: =IF(COUNT(D8:F8)=0,"",AVERAGE(D8:F8)) | H8: =IF(G8="",0,G8*C8/3) | I8: =IF(COUNT(D8:F8)<2,"",MAX(D8:F8)-MIN(D8:F8))
A9: A3 | B9: Organisasi & Kerapian Area Kerja (5S) | C9: 2 | G9: =IF(COUNT(D9:F9)=0,"",AVERAGE(D9:F9)) | H9: =IF(G9="",0,G9*C9/3) | I9: =IF(COUNT(D9:F9)<2,"",MAX(D9:F9)-MIN(D9:F9))
A10: A4 | B10: Restorasi Area Kerja | C10: 2 | G10: =IF(COUNT(D10:F10)=0,"",AVERAGE(D10:F10)) | H10: =IF(G10="",0,G10*C10/3) | I10: =IF(COUNT(D10:F10)<2,"",MAX(D10:F10)-MIN(D10:F10))
B11: TOTAL MODUL A | C11: 8 | H11: =SUM(H7:H10)

Sheet Modul B
A1: MODUL B — Jurnal / Laporan Teknis (10 poin: J 8 + M 2)
A2: Bingung cara nilai Modul B? Buka panduan di GitHub (klik di sini)
A3: Tim No: | C3: Nama Tim: | E3: Kontingen: | G3: Deadline:
A4: Juri 1: | C4: Juri 2: | E4: Juri 3: | G4: Tepat Waktu (1/0):
A6: Kode | B6: Aspek | C6: Tipe | D6: Max | E6: J1 | F6: J2 | G6: J3 | H6: Rata-rata | I6: Skor Akhir | J6: Selisih | K6: Catatan
A7: B-J1 | B7: Kualitas Fabrikasi Rangka & Stabilitas | C7: J | D7: 1.5 | H7: =IF(COUNT(E7:G7)=0,"",AVERAGE(E7:G7)) | I7: =IF(H7="",0,H7*D7/3) | J7: =IF(COUNT(E7:G7)<2,"",MAX(E7:G7)-MIN(E7:G7))
A8: B-J2 | B8: Manajemen Pengkabelan (Wiring) | C8: J | D8: 1.5 | H8: =IF(COUNT(E8:G8)=0,"",AVERAGE(E8:G8)) | I8: =IF(H8="",0,H8*D8/3) | J8: =IF(COUNT(E8:G8)<2,"",MAX(E8:G8)-MIN(E8:G8))
A9: B-J3 | B9: Integrasi Sistem Penggerak | C9: J | D9: 1.5 | H9: =IF(COUNT(E9:G9)=0,"",AVERAGE(E9:G9)) | I9: =IF(H9="",0,H9*D9/3) | J9: =IF(COUNT(E9:G9)<2,"",MAX(E9:G9)-MIN(E9:G9))
A10: B-J4 | B10: Kalibrasi Sensor & Aktuator | C10: J | D10: 1.5 | H10: =IF(COUNT(E10:G10)=0,"",AVERAGE(E10:G10)) | I10: =IF(H10="",0,H10*D10/3) | J10: =IF(COUNT(E10:G10)<2,"",MAX(E10:G10)-MIN(E10:G10))
A11: B-J5 | B11: Optimasi Software-Hardware | C11: J | D11: 1.5 | H11: =IF(COUNT(E11:G11)=0,"",AVERAGE(E11:G11)) | I11: =IF(H11="",0,H11*D11/3) | J11: =IF(COUNT(E11:G11)<2,"",MAX(E11:G11)-MIN(E11:G11))
A12: B-J6 | B12: Kelengkapan Dokumentasi | C12: J | D12: 0.5 | H12: =IF(COUNT(E12:G12)=0,"",AVERAGE(E12:G12)) | I12: =IF(H12="",0,H12*D12/3) | J12: =IF(COUNT(E12:G12)<2,"",MAX(E12:G12)-MIN(E12:G12))
B13: SUBTOTAL JUDGEMENT | D13: 8 | I13: =SUM(I7:I12)
A14: B-M1 | B14: Ketepatan Mengumpulkan sesuai Waktu | C14: M | D14: 2 | I14: =IF(G4="",0,G4*D14)
B15: TOTAL MODUL B | D15: 10 | I15: =I13+I14
A17: CHECKLIST KELENGKAPAN (1=ada)
A18: C1 | B18: Analisis Tugas & Strategi
A19: C2 | B19: Desain Mekanik
A20: C3 | B20: Diagram Blok
A21: C4 | B21: Bill of Materials
A22: C5 | B22: Dokumentasi Fabrikasi
A23: C6 | B23: Manajemen Kelistrikan
A24: C7 | B24: Penempatan Sensor
A25: C8 | B25: Arsitektur Software
A26: C9 | B26: Algoritma Navigasi
A27: C10 | B27: Algoritma Visi
A28: C11 | B28: Flowchart
A29: C12 | B29: Data Kalibrasi
... A31: C14 | B31: Log Troubleshooting

Sheet Modul C
A1: MODUL C — Pembuatan & Perakitan Robot (10 poin, Judgement)
A2: Bingung cara nilai Modul C? Buka panduan di GitHub (klik di sini)
A3: Tim No: | C3: Nama Tim: | E3: Waktu Mulai: | G3: Waktu Selesai: | I3: Durasi (jam):
A4: Juri 1: | C4: Juri 2: | E4: Juri 3:
A6: Sub | B6: Kriteria | C6: Max | D6: J1 | E6: J2 | F6: J3 | G6: Rata-rata | H6: Skor Akhir | I6: Selisih | J6: Catatan
A7: C1 | B7: Perakitan L-Channel sebagai Penyangga Utama Lift | C7: 2.5 | G7: =IF(COUNT(D7:F7)=0,"",AVERAGE(D7:F7)) | H7: =IF(G7="",0,G7*C7/3) | I7: =IF(COUNT(D7:F7)<2,"",MAX(D7:F7)-MIN(D7:F7))
A8: C2 | B8: Integrasi Sistem Angkat / Gripper / Lifter | C8: 2.5 | G8: =IF(COUNT(D8:F8)=0,"",AVERAGE(D8:F8)) | H8: =IF(G8="",0,G8*C8/3) | I8: =IF(COUNT(D8:F8)<2,"",MAX(D8:F8)-MIN(D8:F8))
A9: C3 | B9: Kualitas Rewiring (rapi, aman) | C9: 2.5 | G9: =IF(COUNT(D9:F9)=0,"",AVERAGE(D9:F9)) | H9: =IF(G9="",0,G9*C9/3) | I9: =IF(COUNT(D9:F9)<2,"",MAX(D9:F9)-MIN(D9:F9))
A10: C4 | B10: Kelayakan Operasional (STOP, struktur stabil) | C10: 2.5 | G10: =IF(COUNT(D10:F10)=0,"",AVERAGE(D10:F10)) | H10: =IF(G10="",0,G10*C10/3) | I10: =IF(COUNT(D10:F10)<2,"",MAX(D10:F10)-MIN(D10:F10))
B11: TOTAL MODUL C | C11: 10 | H11: =SUM(H7:H10)
A13: CHECKLIST INSPEKSI (1=Lulus 0=Tidak)
A14: I1 | B14: L-Channel sebagai penyangga utama angkat
A15: I2 | B15: Sistem objek terpasang kuat di L-Channel
A16: I3 | B16: Tidak ada kabel terbuka/terjepit
A17: I4 | B17: Tombol STOP merah berfungsi
A18: I5 | B18: Selesai dalam batas 2 jam
A19: I6 | B19: Robot aman dioperasikan (K3)

Sheet Modul D
A1: MODUL D — Gerakan Dasar & Manajemen Objek (12 poin, Measurement)
A2: Bingung cara nilai Modul D? Buka panduan di GitHub (klik di sini)
A3: Tim No: | C3: Nama Tim: | E3: Tanggal:
A4: Juri Penilai:
A6: ID | B6: Evaluasi | C6: Indikator | D6: Bobot | E6: Hasil (1/0) | F6: Skor | G6: Catatan
A7: D1a | B7: Gerak maju 200-300 mm | C7: Observasi | D7: 0.5 | F7: =IF(E7="",0,E7*D7)
A8: D1b | B8: Gerak mundur 200-300 mm | C8: Observasi | D8: 0.5 | F8: =IF(E8="",0,E8*D8)
A9: D1c | B9: Gerak kanan 200-300 mm | C9: Observasi | D9: 0.5 | F9: =IF(E9="",0,E9*D9)
A10: D1d | B10: Gerak kiri 200-300 mm | C10: Observasi | D10: 0.5 | F10: =IF(E10="",0,E10*D10)
A11: D2a | B11: Maju stop 50-100 mm dari dinding | C11: Observasi | D11: 0.3 | F11: =IF(E11="",0,E11*D11)
A12: D2b | B12: Kanan stop 50-100 mm dari dinding | C12: Observasi | D12: 0.6 | F12: =IF(E12="",0,E12*D12)
A13: D3 | B13: Ikuti garis U | C13: Line follower | D13: 1 | F13: =IF(E13="",0,E13*D13)
A14: D4 | B14: Deteksi merah → teks merah | C14: Monitor | D14: 1 | F14: =IF(E14="",0,E14*D14)
A15: D5 | B15: Deteksi hijau → teks hijau | C15: Monitor | D15: 1 | F15: =IF(E15="",0,E15*D15)
A16: D6 | B16: Deteksi biru → teks biru | C16: Monitor | D16: 1 | F16: =IF(E16="",0,E16*D16)
A17: D7 | B17: Deteksi O-merah | C17: Monitor | D17: 1 | F17: =IF(E17="",0,E17*D17)
A18: D8 | B18: Deteksi O-hijau | C18: Monitor | D18: 1 | F18: =IF(E18="",0,E18*D18)
... A20: D10 | B20: Place kubus ke standbox | C20: Observasi arm | D20: 2 | F20: =IF(E20="",0,E20*D20)
B21: TOTAL (skala 12) | D21: 12 | F21: =ROUND(SUM(F7:F20)*12/12.9,2) | G21: Bobot mentah item = 12.9

Sheet Undian Kubus
A1: LEMBAR UNDIAN POSISI KUBUS — LKS 2026
A2: Bingung cara isi? Buka panduan Undian Kubus di GitHub (klik di sini)
A3: Run ID: | B3: RUN-01 | D3: Tim No: | E3: 05 | G3: Nama Tim: | H3: SMK Contoh
A4: Hari: | B4: H2 | D4: Tanggal: | E4: 24/06/2026 | G4: Arena No: | H4: 2
A5: Fase: | B5: Trial | D5: Juru Acak: | G5: Juri Saksi:
A6: Waktu Undian:
A8: KATALOG KUBUS (referensi — 9 buah)
A9: ID Kubus | B9: Warna | C9: Bentuk | D9: RGB
A10: K-M1 | B10: Merah | C10: Lingkaran | D10: 255-0-0
A11: K-M2 | B11: Merah | C11: Persegi | D11: 255-0-0
A12: K-M3 | B12: Merah | C12: Segitiga | D12: 255-0-0
A13: K-H1 | B13: Hijau | C13: Lingkaran | D13: 0-255-0
A14: K-H2 | B14: Hijau | C14: Persegi | D14: 0-255-0
A15: K-H3 | B15: Hijau | C15: Segitiga | D15: 0-255-0
A16: K-B1 | B16: Biru | C16: Lingkaran | D16: 0-0-255
A17: K-B2 | B17: Biru | C17: Persegi | D17: 0-0-255
A18: K-B3 | B18: Biru | C18: Segitiga | D18: 0-0-255
A20: KONFIGURASI MARKER RAK — isi warna di baris 24 (ketik: Merah / Hijau / Biru)
A21: KETERANGAN: R1–R3 = Rak 1–3 di arena (3 buah rak, masing-masing 3 slot). S1/S2/S3 = Slot kiri / tengah / kanan (dilihat dari depan rak). Marker = warna label di ATAS slot — kubus sukses jika ditaruh di slot yang marker-nya sama warnanya dengan kubus.
A22: ▼ RAK 1 | D22: ▼ RAK 2 | G22: ▼ RAK 3
A23: Rak1 · kiri | B23: Rak1 · tengah | C23: Rak1 · kanan | D23: Rak2 · kiri | E23: Rak2 · tengah | F23: Rak2 · kanan | G23: Rak3 · kiri | H23: Rak3 · tengah | I23: Rak3 · kanan
A24: Merah | B24: Hijau | C24: Biru | D24: Biru | E24: Merah | F24: Hijau | G24: Hijau | H24: Biru | I24: Merah
A25: POSISI AWAL SETELAH UNDIAN (isi ID kubus — kolom lain otomatis)
A27: ID Kubus | B27: Warna | C27: Bentuk | D27: Lokasi Awal | E27: Rak/Stand | F27: Slot | G27: Sudah Benar (1/0) | H27: Target Rak | I27: Target Marker | J27: Perlu Dipindah? | K27: Catatan
A28: K-M1 | B28: =IF(A28="","",VLOOKUP(A28,'Undian Kubus'!$A$10:$D$18,2,FALSE)) | C28: =IF(A28="","",VLOOKUP(A28,'Undian Kubus'!$A$10:$D$18,3,FALSE)) | D28: =IF(A28="","",IF(E28="","(belum diisi — isi kolom E & F)",TRIM(E28&IF(F28<>""," — "&F28,"")))) | E28: Rak 1 | F28: kiri | G28: =IF(OR(A28="",E28="",F28=""),"",IF(OR(AND(OR(E28="Rak 1",E28="R1"),OR(LOWER(F28)="kiri",LOWER(F28)="s1",LOWER(F28)="r1-s1"),$A$24=B28),AND(OR(E28="Rak 1",E28="R1"),OR(LOWER(F28)="tengah",LOWER(F28)="s2",LOWER(F28)="r1-s2"),$B$24=B28),AND(OR(E28="Rak 1",E28="R1"),OR(LOWER(F28)="kanan",LOWER(F28)="s3",LOWER(F28)="r1-s3"),$C$24=B28),AND(OR(E28="Rak 2",E28="R2"),OR(LOWER(F28)="kiri",LOWER(F28)="s1",LOWER(F28)="r2-s1"),$D$24=B28),AND(OR(E28="Rak 2",E28="R2"),OR(LOWER(F28)="tengah",LOWER(F28)="s2",LOWER(F28)="r2-s2"),$E$24=B28),AND(OR(E28="Rak 2",E28="R2"),OR(LOWER(F28)="kanan",LOWER(F28)="s3",LOWER(F28)="r2-s3"),$F$24=B28),AND(OR(E28="Rak 3",E28="R3"),OR(LOWER(F28)="kiri",LOWER(F28)="s1",LOWER(F28)="r3-s1"),$G$24=B28),AND(OR(E28="Rak 3",E28="R3"),OR(LOWER(F28)="tengah",LOWER(F28)="s2",LOWER(F28)="r3-s2"),$H$24=B28),AND(OR(E28="Rak 3",E28="R3"),OR(LOWER(F28)="kanan",LOWER(F28)="s3",LOWER(F28)="r3-s3"),$I$24=B28)),1,0)) | H28: =IF(B28="","",IF(COUNTA($A$24:$I$24)=0,"(isi warna marker baris 24)",IF(IF(COUNTIF($A$24:$C$24,B28)>0,"Rak 1, ","")&IF(COUNTIF($D$24:$F$24,B28)>0,"Rak 2, ","")&IF(COUNTIF($G$24:$I$24,B28)>0,"Rak 3, ","")="","",IF(LEN(IF(COUNTIF($A$24:$C$24,B28)>0,"Rak 1, ","")&IF(COUNTIF($D$24:$F$24,B28)>0,"Rak 2, ","")&IF(COUNTIF($G$24:$I$24,B28)>0,"Rak 3, ",""))>2,LEFT(IF(COUNTIF($A$24:$C$24,B28)>0,"Rak 1, ","")&IF(COUNTIF($D$24:$F$24,B28)>0,"Rak 2, ","")&IF(COUNTIF($G$24:$I$24,B28)>0,"Rak 3, ",""),LEN(IF(COUNTIF($A$24:$C$24,B28)>0,"Rak 1, ","")&IF(COUNTIF($D$24:$F$24,B28)>0,"Rak 2, ","")&IF(COUNTIF($G$24:$I$24,B28)>0,"Rak 3, ",""))-2),IF(COUNTIF($A$24:$C$24,B28)>0,"Rak 1, ","")&IF(COUNTIF($D$24:$F$24,B28)>0,"Rak 2, ","")&IF(COUNTIF($G$24:$I$24,B28)>0,"Rak 3, ",""))))) | I28: =IF(B28="","",IF(COUNTA($A$24:$I$24)=0,"(isi warna marker baris 24)",IF(IF(IF($A$24=B28,"R1-S1 (Rak1 kiri), ","")&IF($B$24=B28,"R1-S2 (Rak1 tengah), ","")&IF($C$24=B28,"R1-S3 (Rak1 kanan), ","")&IF($D$24=B28,"R2-S1 (Rak2 kiri), ","")&IF($E$24=B28,"R2-S2 (Rak2 tengah), ","")&IF($F$24=B28,"R2-S3 (Rak2 kanan), ","")&IF($G$24=B28,"R3-S1 (Rak3 kiri), ","")&IF($H$24=B28,"R3-S2 (Rak3 tengah), ","")&IF($I$24=B28,"R3-S3 (Rak3 kanan), ","")="","",IF(LEN(IF($A$24=B28,"R1-S1 (Rak1 kiri), ","")&IF($B$24=B28,"R1-S2 (Rak1 tengah), ","")&IF($C$24=B28,"R1-S3 (Rak1 kanan), ","")&IF($D$24=B28,"R2-S1 (Rak2 kiri), ","")&IF($E$24=B28,"R2-S2 (Rak2 tengah), ","")&IF($F$24=B28,"R2-S3 (Rak2 kanan), ","")&IF($G$24=B28,"R3-S1 (Rak3 kiri), ","")&IF($H$24=B28,"R3-S2 (Rak3 tengah), ","")&IF($I$24=B28,"R3-S3 (Rak3 kanan), ",""))>2,LEFT(IF($A$24=B28,"R1-S1 (Rak1 kiri), ","")&IF($B$24=B28,"R1-S2 (Rak1 tengah), ","")&IF($C$24=B28,"R1-S3 (Rak1 kanan), ","")&IF($D$24=B28,"R2-S1 (Rak2 kiri), ","")&IF($E$24=B28,"R2-S2 (Rak2 tengah), ","")&IF($F$24=B28,"R2-S3 (Rak2 kanan), ","")&IF($G$24=B28,"R3-S1 (Rak3 kiri), ","")&IF($H$24=B28,"R3-S2 (Rak3 tengah), ","")&IF($I$24=B28,"R3-S3 (Rak3 kanan), ",""),LEN(IF($A$24=B28,"R1-S1 (Rak1 kiri), ","")&IF($B$24=B28,"R1-S2 (Rak1 tengah), ","")&IF($C$24=B28,"R1-S3 (Rak1 kanan), ","")&IF($D$24=B28,"R2-S1 (Rak2 kiri), ","")&IF($E$24=B28,"R2-S2 (Rak2 tengah), ","")&IF($F$24=B28,"R2-S3 (Rak2 kanan), ","")&IF($G$24=B28,"R3-S1 (Rak3 kiri), ","")&IF($H$24=B28,"R3-S2 (Rak3 tengah), ","")&IF($I$24=B28,"R3-S3 (Rak3 kanan), ",""))-2),IF($A$24=B28,"R1-S1 (Rak1 kiri), ","")&IF($B$24=B28,"R1-S2 (Rak1 tengah), ","")&IF($C$24=B28,"R1-S3 (Rak1 kanan), ","")&IF($D$24=B28,"R2-S1 (Rak2 kiri), ","")&IF($E$24=B28,"R2-S2 (Rak2 tengah), ","")&IF($F$24=B28,"R2-S3 (Rak2 kanan), ","")&IF($G$24=B28,"R3-S1 (Rak3 kiri), ","")&IF($H$24=B28,"R3-S2 (Rak3 tengah), ","")&IF($I$24=B28,"R3-S3 (Rak3 kanan), ","")))="","","Slot marker "&B28&": "&IF(IF($A$24=B28,"R1-S1 (Rak1 kiri), ","")&IF($B$24=B28,"R1-S2 (Rak1 tengah), ","")&IF($C$24=B28,"R1-S3 (Rak1 kanan), ","")&IF($D$24=B28,"R2-S1 (Rak2 kiri), ","")&IF($E$24=B28,"R2-S2 (Rak2 tengah), ","")&IF($F$24=B28,"R2-S3 (Rak2 kanan), ","")&IF($G$24=B28,"R3-S1 (Rak3 kiri), ","")&IF($H$24=B28,"R3-S2 (Rak3 tengah), ","")&IF($I$24=B28,"R3-S3 (Rak3 kanan), ","")="","",IF(LEN(IF($A$24=B28,"R1-S1 (Rak1 kiri), ","")&IF($B$24=B28,"R1-S2 (Rak1 tengah), ","")&IF($C$24=B28,"R1-S3 (Rak1 kanan), ","")&IF($D$24=B28,"R2-S1 (Rak2 kiri), ","")&IF($E$24=B28,"R2-S2 (Rak2 tengah), ","")&IF($F$24=B28,"R2-S3 (Rak2 kanan), ","")&IF($G$24=B28,"R3-S1 (Rak3 kiri), ","")&IF($H$24=B28,"R3-S2 (Rak3 tengah), ","")&IF($I$24=B28,"R3-S3 (Rak3 kanan), ",""))>2,LEFT(IF($A$24=B28,"R1-S1 (Rak1 kiri), ","")&IF($B$24=B28,"R1-S2 (Rak1 tengah), ","")&IF($C$24=B28,"R1-S3 (Rak1 kanan), ","")&IF($D$24=B28,"R2-S1 (Rak2 kiri), ","")&IF($E$24=B28,"R2-S2 (Rak2 tengah), ","")&IF($F$24=B28,"R2-S3 (Rak2 kanan), ","")&IF($G$24=B28,"R3-S1 (Rak3 kiri), ","")&IF($H$24=B28,"R3-S2 (Rak3 tengah), ","")&IF($I$24=B28,"R3-S3 (Rak3 kanan), ",""),LEN(IF($A$24=B28,"R1-S1 (Rak1 kiri), ","")&IF($B$24=B28,"R1-S2 (Rak1 tengah), ","")&IF($C$24=B28,"R1-S3 (Rak1 kanan), ","")&IF($D$24=B28,"R2-S1 (Rak2 kiri), ","")&IF($E$24=B28,"R2-S2 (Rak2 tengah), ","")&IF($F$24=B28,"R2-S3 (Rak2 kanan), ","")&IF($G$24=B28,"R3-S1 (Rak3 kiri), ","")&IF($H$24=B28,"R3-S2 (Rak3 tengah), ","")&IF($I$24=B28,"R3-S3 (Rak3 kanan), ",""))-2),IF($A$24=B28,"R1-S1 (Rak1 kiri), ","")&IF($B$24=B28,"R1-S2 (Rak1 tengah), ","")&IF($C$24=B28,"R1-S3 (Rak1 kanan), ","")&IF($D$24=B28,"R2-S1 (Rak2 kiri), ","")&IF($E$24=B28,"R2-S2 (Rak2 tengah), ","")&IF($F$24=B28,"R2-S3 (Rak2 kanan), ","")&IF($G$24=B28,"R3-S1 (Rak3 kiri), ","")&IF($H$24=B28,"R3-S2 (Rak3 tengah), ","")&IF($I$24=B28,"R3-S3 (Rak3 kanan), ","")))))) | J28: =IF(G28="","",IF(G28=1,0,1))
A29: K-M2 | B29: =IF(A29="","",VLOOKUP(A29,'Undian Kubus'!$A$10:$D$18,2,FALSE)) | C29: =IF(A29="","",VLOOKUP(A29,'Undian Kubus'!$A$10:$D$18,3,FALSE)) | D29: =IF(A29="","",IF(E29="","(belum diisi — isi kolom E & F)",TRIM(E29&IF(F29<>""," — "&F29,"")))) | E29: Stand A | F29: depan | G29: =IF(OR(A29="",E29="",F29=""),"",IF(OR(AND(OR(E29="Rak 1",E29="R1"),OR(LOWER(F29)="kiri",LOWER(F29)="s1",LOWER(F29)="r1-s1"),$A$24=B29),AND(OR(E29="Rak 1",E29="R1"),OR(LOWER(F29)="tengah",LOWER(F29)="s2",LOWER(F29)="r1-s2"),$B$24=B29),AND(OR(E29="Rak 1",E29="R1"),OR(LOWER(F29)="kanan",LOWER(F29)="s3",LOWER(F29)="r1-s3"),$C$24=B29),AND(OR(E29="Rak 2",E29="R2"),OR(LOWER(F29)="kiri",LOWER(F29)="s1",LOWER(F29)="r2-s1"),$D$24=B29),AND(OR(E29="Rak 2",E29="R2"),OR(LOWER(F29)="tengah",LOWER(F29)="s2",LOWER(F29)="r2-s2"),$E$24=B29),AND(OR(E29="Rak 2",E29="R2"),OR(LOWER(F29)="kanan",LOWER(F29)="s3",LOWER(F29)="r2-s3"),$F$24=B29),AND(OR(E29="Rak 3",E29="R3"),OR(LOWER(F29)="kiri",LOWER(F29)="s1",LOWER(F29)="r3-s1"),$G$24=B29),AND(OR(E29="Rak 3",E29="R3"),OR(LOWER(F29)="tengah",LOWER(F29)="s2",LOWER(F29)="r3-s2"),$H$24=B29),AND(OR(E29="Rak 3",E29="R3"),OR(LOWER(F29)="kanan",LOWER(F29)="s3",LOWER(F29)="r3-s3"),$I$24=B29)),1,0)) | H29: =IF(B29="","",IF(COUNTA($A$24:$I$24)=0,"(isi warna marker baris 24)",IF(IF(COUNTIF($A$24:$C$24,B29)>0,"Rak 1, ","")&IF(COUNTIF($D$24:$F$24,B29)>0,"Rak 2, ","")&IF(COUNTIF($G$24:$I$24,B29)>0,"Rak 3, ","")="","",IF(LEN(IF(COUNTIF($A$24:$C$24,B29)>0,"Rak 1, ","")&IF(COUNTIF($D$24:$F$24,B29)>0,"Rak 2, ","")&IF(COUNTIF($G$24:$I$24,B29)>0,"Rak 3, ",""))>2,LEFT(IF(COUNTIF($A$24:$C$24,B29)>0,"Rak 1, ","")&IF(COUNTIF($D$24:$F$24,B29)>0,"Rak 2, ","")&IF(COUNTIF($G$24:$I$24,B29)>0,"Rak 3, ",""),LEN(IF(COUNTIF($A$24:$C$24,B29)>0,"Rak 1, ","")&IF(COUNTIF($D$24:$F$24,B29)>0,"Rak 2, ","")&IF(COUNTIF($G$24:$I$24,B29)>0,"Rak 3, ",""))-2),IF(COUNTIF($A$24:$C$24,B29)>0,"Rak 1, ","")&IF(COUNTIF($D$24:$F$24,B29)>0,"Rak 2, ","")&IF(COUNTIF($G$24:$I$24,B29)>0,"Rak 3, ",""))))) | I29: =IF(B29="","",IF(COUNTA($A$24:$I$24)=0,"(isi warna marker baris 24)",IF(IF(IF($A$24=B29,"R1-S1 (Rak1 kiri), ","")&IF($B$24=B29,"R1-S2 (Rak1 tengah), ","")&IF($C$24=B29,"R1-S3 (Rak1 kanan), ","")&IF($D$24=B29,"R2-S1 (Rak2 kiri), ","")&IF($E$24=B29,"R2-S2 (Rak2 tengah), ","")&IF($F$24=B29,"R2-S3 (Rak2 kanan), ","")&IF($G$24=B29,"R3-S1 (Rak3 kiri), ","")&IF($H$24=B29,"R3-S2 (Rak3 tengah), ","")&IF($I$24=B29,"R3-S3 (Rak3 kanan), ","")="","",IF(LEN(IF($A$24=B29,"R1-S1 (Rak1 kiri), ","")&IF($B$24=B29,"R1-S2 (Rak1 tengah), ","")&IF($C$24=B29,"R1-S3 (Rak1 kanan), ","")&IF($D$24=B29,"R2-S1 (Rak2 kiri), ","")&IF($E$24=B29,"R2-S2 (Rak2 tengah), ","")&IF($F$24=B29,"R2-S3 (Rak2 kanan), ","")&IF($G$24=B29,"R3-S1 (Rak3 kiri), ","")&IF($H$24=B29,"R3-S2 (Rak3 tengah), ","")&IF($I$24=B29,"R3-S3 (Rak3 kanan), ",""))>2,LEFT(IF($A$24=B29,"R1-S1 (Rak1 kiri), ","")&IF($B$24=B29,"R1-S2 (Rak1 tengah), ","")&IF($C$24=B29,"R1-S3 (Rak1 kanan), ","")&IF($D$24=B29,"R2-S1 (Rak2 kiri), ","")&IF($E$24=B29,"R2-S2 (Rak2 tengah), ","")&IF($F$24=B29,"R2-S3 (Rak2 kanan), ","")&IF($G$24=B29,"R3-S1 (Rak3 kiri), ","")&IF($H$24=B29,"R3-S2 (Rak3 tengah), ","")&IF($I$24=B29,"R3-S3 (Rak3 kanan), ",""),LEN(IF($A$24=B29,"R1-S1 (Rak1 kiri), ","")&IF($B$24=B29,"R1-S2 (Rak1 tengah), ","")&IF($C$24=B29,"R1-S3 (Rak1 kanan), ","")&IF($D$24=B29,"R2-S1 (Rak2 kiri), ","")&IF($E$24=B29,"R2-S2 (Rak2 tengah), ","")&IF($F$24=B29,"R2-S3 (Rak2 kanan), ","")&IF($G$24=B29,"R3-S1 (Rak3 kiri), ","")&IF($H$24=B29,"R3-S2 (Rak3 tengah), ","")&IF($I$24=B29,"R3-S3 (Rak3 kanan), ",""))-2),IF($A$24=B29,"R1-S1 (Rak1 kiri), ","")&IF($B$24=B29,"R1-S2 (Rak1 tengah), ","")&IF($C$24=B29,"R1-S3 (Rak1 kanan), ","")&IF($D$24=B29,"R2-S1 (Rak2 kiri), ","")&IF($E$24=B29,"R2-S2 (Rak2 tengah), ","")&IF($F$24=B29,"R2-S3 (Rak2 kanan), ","")&IF($G$24=B29,"R3-S1 (Rak3 kiri), ","")&IF($H$24=B29,"R3-S2 (Rak3 tengah), ","")&IF($I$24=B29,"R3-S3 (Rak3 kanan), ","")))="","","Slot marker "&B29&": "&IF(IF($A$24=B29,"R1-S1 (Rak1 kiri), ","")&IF($B$24=B29,"R1-S2 (Rak1 tengah), ","")&IF($C$24=B29,"R1-S3 (Rak1 kanan), ","")&IF($D$24=B29,"R2-S1 (Rak2 kiri), ","")&IF($E$24=B29,"R2-S2 (Rak2 tengah), ","")&IF($F$24=B29,"R2-S3 (Rak2 kanan), ","")&IF($G$24=B29,"R3-S1 (Rak3 kiri), ","")&IF($H$24=B29,"R3-S2 (Rak3 tengah), ","")&IF($I$24=B29,"R3-S3 (Rak3 kanan), ","")="","",IF(LEN(IF($A$24=B29,"R1-S1 (Rak1 kiri), ","")&IF($B$24=B29,"R1-S2 (Rak1 tengah), ","")&IF($C$24=B29,"R1-S3 (Rak1 kanan), ","")&IF($D$24=B29,"R2-S1 (Rak2 kiri), ","")&IF($E$24=B29,"R2-S2 (Rak2 tengah), ","")&IF($F$24=B29,"R2-S3 (Rak2 kanan), ","")&IF($G$24=B29,"R3-S1 (Rak3 kiri), ","")&IF($H$24=B29,"R3-S2 (Rak3 tengah), ","")&IF($I$24=B29,"R3-S3 (Rak3 kanan), ",""))>2,LEFT(IF($A$24=B29,"R1-S1 (Rak1 kiri), ","")&IF($B$24=B29,"R1-S2 (Rak1 tengah), ","")&IF($C$24=B29,"R1-S3 (Rak1 kanan), ","")&IF($D$24=B29,"R2-S1 (Rak2 kiri), ","")&IF($E$24=B29,"R2-S2 (Rak2 tengah), ","")&IF($F$24=B29,"R2-S3 (Rak2 kanan), ","")&IF($G$24=B29,"R3-S1 (Rak3 kiri), ","")&IF($H$24=B29,"R3-S2 (Rak3 tengah), ","")&IF($I$24=B29,"R3-S3 (Rak3 kanan), ",""),LEN(IF($A$24=B29,"R1-S1 (Rak1 kiri), ","")&IF($B$24=B29,"R1-S2 (Rak1 tengah), ","")&IF($C$24=B29,"R1-S3 (Rak1 kanan), ","")&IF($D$24=B29,"R2-S1 (Rak2 kiri), ","")&IF($E$24=B29,"R2-S2 (Rak2 tengah), ","")&IF($F$24=B29,"R2-S3 (Rak2 kanan), ","")&IF($G$24=B29,"R3-S1 (Rak3 kiri), ","")&IF($H$24=B29,"R3-S2 (Rak3 tengah), ","")&IF($I$24=B29,"R3-S3 (Rak3 kanan), ",""))-2),IF($A$24=B29,"R1-S1 (Rak1 kiri), ","")&IF($B$24=B29,"R1-S2 (Rak1 tengah), ","")&IF($C$24=B29,"R1-S3 (Rak1 kanan), ","")&IF($D$24=B29,"R2-S1 (Rak2 kiri), ","")&IF($E$24=B29,"R2-S2 (Rak2 tengah), ","")&IF($F$24=B29,"R2-S3 (Rak2 kanan), ","")&IF($G$24=B29,"R3-S1 (Rak3 kiri), ","")&IF($H$24=B29,"R3-S2 (Rak3 tengah), ","")&IF($I$24=B29,"R3-S3 (Rak3 kanan), ","")))))) | J29: =IF(G29="","",IF(G29=1,0,1))
A30: K-M3 | B30: =IF(A30="","",VLOOKUP(A30,'Undian Kubus'!$A$10:$D$18,2,FALSE)) | C30: =IF(A30="","",VLOOKUP(A30,'Undian Kubus'!$A$10:$D$18,3,FALSE)) | D30: =IF(A30="","",IF(E30="","(belum diisi — isi kolom E & F)",TRIM(E30&IF(F30<>""," — "&F30,"")))) | E30: Rak 2 | F30: tengah | G30: =IF(OR(A30="",E30="",F30=""),"",IF(OR(AND(OR(E30="Rak 1",E30="R1"),OR(LOWER(F30)="kiri",LOWER(F30)="s1",LOWER(F30)="r1-s1"),$A$24=B30),AND(OR(E30="Rak 1",E30="R1"),OR(LOWER(F30)="tengah",LOWER(F30)="s2",LOWER(F30)="r1-s2"),$B$24=B30),AND(OR(E30="Rak 1",E30="R1"),OR(LOWER(F30)="kanan",LOWER(F30)="s3",LOWER(F30)="r1-s3"),$C$24=B30),AND(OR(E30="Rak 2",E30="R2"),OR(LOWER(F30)="kiri",LOWER(F30)="s1",LOWER(F30)="r2-s1"),$D$24=B30),AND(OR(E30="Rak 2",E30="R2"),OR(LOWER(F30)="tengah",LOWER(F30)="s2",LOWER(F30)="r2-s2"),$E$24=B30),AND(OR(E30="Rak 2",E30="R2"),OR(LOWER(F30)="kanan",LOWER(F30)="s3",LOWER(F30)="r2-s3"),$F$24=B30),AND(OR(E30="Rak 3",E30="R3"),OR(LOWER(F30)="kiri",LOWER(F30)="s1",LOWER(F30)="r3-s1"),$G$24=B30),AND(OR(E30="Rak 3",E30="R3"),OR(LOWER(F30)="tengah",LOWER(F30)="s2",LOWER(F30)="r3-s2"),$H$24=B30),AND(OR(E30="Rak 3",E30="R3"),OR(LOWER(F30)="kanan",LOWER(F30)="s3",LOWER(F30)="r3-s3"),$I$24=B30)),1,0)) | H30: =IF(B30="","",IF(COUNTA($A$24:$I$24)=0,"(isi warna marker baris 24)",IF(IF(COUNTIF($A$24:$C$24,B30)>0,"Rak 1, ","")&IF(COUNTIF($D$24:$F$24,B30)>0,"Rak 2, ","")&IF(COUNTIF($G$24:$I$24,B30)>0,"Rak 3, ","")="","",IF(LEN(IF(COUNTIF($A$24:$C$24,B30)>0,"Rak 1, ","")&IF(COUNTIF($D$24:$F$24,B30)>0,"Rak 2, ","")&IF(COUNTIF($G$24:$I$24,B30)>0,"Rak 3, ",""))>2,LEFT(IF(COUNTIF($A$24:$C$24,B30)>0,"Rak 1, ","")&IF(COUNTIF($D$24:$F$24,B30)>0,"Rak 2, ","")&IF(COUNTIF($G$24:$I$24,B30)>0,"Rak 3, ",""),LEN(IF(COUNTIF($A$24:$C$24,B30)>0,"Rak 1, ","")&IF(COUNTIF($D$24:$F$24,B30)>0,"Rak 2, ","")&IF(COUNTIF($G$24:$I$24,B30)>0,"Rak 3, ",""))-2),IF(COUNTIF($A$24:$C$24,B30)>0,"Rak 1, ","")&IF(COUNTIF($D$24:$F$24,B30)>0,"Rak 2, ","")&IF(COUNTIF($G$24:$I$24,B30)>0,"Rak 3, ",""))))) | I30: =IF(B30="","",IF(COUNTA($A$24:$I$24)=0,"(isi warna marker baris 24)",IF(IF(IF($A$24=B30,"R1-S1 (Rak1 kiri), ","")&IF($B$24=B30,"R1-S2 (Rak1 tengah), ","")&IF($C$24=B30,"R1-S3 (Rak1 kanan), ","")&IF($D$24=B30,"R2-S1 (Rak2 kiri), ","")&IF($E$24=B30,"R2-S2 (Rak2 tengah), ","")&IF($F$24=B30,"R2-S3 (Rak2 kanan), ","")&IF($G$24=B30,"R3-S1 (Rak3 kiri), ","")&IF($H$24=B30,"R3-S2 (Rak3 tengah), ","")&IF($I$24=B30,"R3-S3 (Rak3 kanan), ","")="","",IF(LEN(IF($A$24=B30,"R1-S1 (Rak1 kiri), ","")&IF($B$24=B30,"R1-S2 (Rak1 tengah), ","")&IF($C$24=B30,"R1-S3 (Rak1 kanan), ","")&IF($D$24=B30,"R2-S1 (Rak2 kiri), ","")&IF($E$24=B30,"R2-S2 (Rak2 tengah), ","")&IF($F$24=B30,"R2-S3 (Rak2 kanan), ","")&IF($G$24=B30,"R3-S1 (Rak3 kiri), ","")&IF($H$24=B30,"R3-S2 (Rak3 tengah), ","")&IF($I$24=B30,"R3-S3 (Rak3 kanan), ",""))>2,LEFT(IF($A$24=B30,"R1-S1 (Rak1 kiri), ","")&IF($B$24=B30,"R1-S2 (Rak1 tengah), ","")&IF($C$24=B30,"R1-S3 (Rak1 kanan), ","")&IF($D$24=B30,"R2-S1 (Rak2 kiri), ","")&IF($E$24=B30,"R2-S2 (Rak2 tengah), ","")&IF($F$24=B30,"R2-S3 (Rak2 kanan), ","")&IF($G$24=B30,"R3-S1 (Rak3 kiri), ","")&IF($H$24=B30,"R3-S2 (Rak3 tengah), ","")&IF($I$24=B30,"R3-S3 (Rak3 kanan), ",""),LEN(IF($A$24=B30,"R1-S1 (Rak1 kiri), ","")&IF($B$24=B30,"R1-S2 (Rak1 tengah), ","")&IF($C$24=B30,"R1-S3 (Rak1 kanan), ","")&IF($D$24=B30,"R2-S1 (Rak2 kiri), ","")&IF($E$24=B30,"R2-S2 (Rak2 tengah), ","")&IF($F$24=B30,"R2-S3 (Rak2 kanan), ","")&IF($G$24=B30,"R3-S1 (Rak3 kiri), ","")&IF($H$24=B30,"R3-S2 (Rak3 tengah), ","")&IF($I$24=B30,"R3-S3 (Rak3 kanan), ",""))-2),IF($A$24=B30,"R1-S1 (Rak1 kiri), ","")&IF($B$24=B30,"R1-S2 (Rak1 tengah), ","")&IF($C$24=B30,"R1-S3 (Rak1 kanan), ","")&IF($D$24=B30,"R2-S1 (Rak2 kiri), ","")&IF($E$24=B30,"R2-S2 (Rak2 tengah), ","")&IF($F$24=B30,"R2-S3 (Rak2 kanan), ","")&IF($G$24=B30,"R3-S1 (Rak3 kiri), ","")&IF($H$24=B30,"R3-S2 (Rak3 tengah), ","")&IF($I$24=B30,"R3-S3 (Rak3 kanan), ","")))="","","Slot marker "&B30&": "&IF(IF($A$24=B30,"R1-S1 (Rak1 kiri), ","")&IF($B$24=B30,"R1-S2 (Rak1 tengah), ","")&IF($C$24=B30,"R1-S3 (Rak1 kanan), ","")&IF($D$24=B30,"R2-S1 (Rak2 kiri), ","")&IF($E$24=B30,"R2-S2 (Rak2 tengah), ","")&IF($F$24=B30,"R2-S3 (Rak2 kanan), ","")&IF($G$24=B30,"R3-S1 (Rak3 kiri), ","")&IF($H$24=B30,"R3-S2 (Rak3 tengah), ","")&IF($I$24=B30,"R3-S3 (Rak3 kanan), ","")="","",IF(LEN(IF($A$24=B30,"R1-S1 (Rak1 kiri), ","")&IF($B$24=B30,"R1-S2 (Rak1 tengah), ","")&IF($C$24=B30,"R1-S3 (Rak1 kanan), ","")&IF($D$24=B30,"R2-S1 (Rak2 kiri), ","")&IF($E$24=B30,"R2-S2 (Rak2 tengah), ","")&IF($F$24=B30,"R2-S3 (Rak2 kanan), ","")&IF($G$24=B30,"R3-S1 (Rak3 kiri), ","")&IF($H$24=B30,"R3-S2 (Rak3 tengah), ","")&IF($I$24=B30,"R3-S3 (Rak3 kanan), ",""))>2,LEFT(IF($A$24=B30,"R1-S1 (Rak1 kiri), ","")&IF($B$24=B30,"R1-S2 (Rak1 tengah), ","")&IF($C$24=B30,"R1-S3 (Rak1 kanan), ","")&IF($D$24=B30,"R2-S1 (Rak2 kiri), ","")&IF($E$24=B30,"R2-S2 (Rak2 tengah), ","")&IF($F$24=B30,"R2-S3 (Rak2 kanan), ","")&IF($G$24=B30,"R3-S1 (Rak3 kiri), ","")&IF($H$24=B30,"R3-S2 (Rak3 tengah), ","")&IF($I$24=B30,"R3-S3 (Rak3 kanan), ",""),LEN(IF($A$24=B30,"R1-S1 (Rak1 kiri), ","")&IF($B$24=B30,"R1-S2 (Rak1 tengah), ","")&IF($C$24=B30,"R1-S3 (Rak1 kanan), ","")&IF($D$24=B30,"R2-S1 (Rak2 kiri), ","")&IF($E$24=B30,"R2-S2 (Rak2 tengah), ","")&IF($F$24=B30,"R2-S3 (Rak2 kanan), ","")&IF($G$24=B30,"R3-S1 (Rak3 kiri), ","")&IF($H$24=B30,"R3-S2 (Rak3 tengah), ","")&IF($I$24=B30,"R3-S3 (Rak3 kanan), ",""))-2),IF($A$24=B30,"R1-S1 (Rak1 kiri), ","")&IF($B$24=B30,"R1-S2 (Rak1 tengah), ","")&IF($C$24=B30,"R1-S3 (Rak1 kanan), ","")&IF($D$24=B30,"R2-S1 (Rak2 kiri), ","")&IF($E$24=B30,"R2-S2 (Rak2 tengah), ","")&IF($F$24=B30,"R2-S3 (Rak2 kanan), ","")&IF($G$24=B30,"R3-S1 (Rak3 kiri), ","")&IF($H$24=B30,"R3-S2 (Rak3 tengah), ","")&IF($I$24=B30,"R3-S3 (Rak3 kanan), ","")))))) | J30: =IF(G30="","",IF(G30=1,0,1))
A31: K-H1 | B31: =IF(A31="","",VLOOKUP(A31,'Undian Kubus'!$A$10:$D$18,2,FALSE)) | C31: =IF(A31="","",VLOOKUP(A31,'Undian Kubus'!$A$10:$D$18,3,FALSE)) | D31: =IF(A31="","",IF(E31="","(belum diisi — isi kolom E & F)",TRIM(E31&IF(F31<>""," — "&F31,"")))) | E31: Rak 3 | F31: kiri | G31: =IF(OR(A31="",E31="",F31=""),"",IF(OR(AND(OR(E31="Rak 1",E31="R1"),OR(LOWER(F31)="kiri",LOWER(F31)="s1",LOWER(F31)="r1-s1"),$A$24=B31),AND(OR(E31="Rak 1",E31="R1"),OR(LOWER(F31)="tengah",LOWER(F31)="s2",LOWER(F31)="r1-s2"),$B$24=B31),AND(OR(E31="Rak 1",E31="R1"),OR(LOWER(F31)="kanan",LOWER(F31)="s3",LOWER(F31)="r1-s3"),$C$24=B31),AND(OR(E31="Rak 2",E31="R2"),OR(LOWER(F31)="kiri",LOWER(F31)="s1",LOWER(F31)="r2-s1"),$D$24=B31),AND(OR(E31="Rak 2",E31="R2"),OR(LOWER(F31)="tengah",LOWER(F31)="s2",LOWER(F31)="r2-s2"),$E$24=B31),AND(OR(E31="Rak 2",E31="R2"),OR(LOWER(F31)="kanan",LOWER(F31)="s3",LOWER(F31)="r2-s3"),$F$24=B31),AND(OR(E31="Rak 3",E31="R3"),OR(LOWER(F31)="kiri",LOWER(F31)="s1",LOWER(F31)="r3-s1"),$G$24=B31),AND(OR(E31="Rak 3",E31="R3"),OR(LOWER(F31)="tengah",LOWER(F31)="s2",LOWER(F31)="r3-s2"),$H$24=B31),AND(OR(E31="Rak 3",E31="R3"),OR(LOWER(F31)="kanan",LOWER(F31)="s3",LOWER(F31)="r3-s3"),$I$24=B31)),1,0)) | H31: =IF(B31="","",IF(COUNTA($A$24:$I$24)=0,"(isi warna marker baris 24)",IF(IF(COUNTIF($A$24:$C$24,B31)>0,"Rak 1, ","")&IF(COUNTIF($D$24:$F$24,B31)>0,"Rak 2, ","")&IF(COUNTIF($G$24:$I$24,B31)>0,"Rak 3, ","")="","",IF(LEN(IF(COUNTIF($A$24:$C$24,B31)>0,"Rak 1, ","")&IF(COUNTIF($D$24:$F$24,B31)>0,"Rak 2, ","")&IF(COUNTIF($G$24:$I$24,B31)>0,"Rak 3, ",""))>2,LEFT(IF(COUNTIF($A$24:$C$24,B31)>0,"Rak 1, ","")&IF(COUNTIF($D$24:$F$24,B31)>0,"Rak 2, ","")&IF(COUNTIF($G$24:$I$24,B31)>0,"Rak 3, ",""),LEN(IF(COUNTIF($A$24:$C$24,B31)>0,"Rak 1, ","")&IF(COUNTIF($D$24:$F$24,B31)>0,"Rak 2, ","")&IF(COUNTIF($G$24:$I$24,B31)>0,"Rak 3, ",""))-2),IF(COUNTIF($A$24:$C$24,B31)>0,"Rak 1, ","")&IF(COUNTIF($D$24:$F$24,B31)>0,"Rak 2, ","")&IF(COUNTIF($G$24:$I$24,B31)>0,"Rak 3, ",""))))) | I31: =IF(B31="","",IF(COUNTA($A$24:$I$24)=0,"(isi warna marker baris 24)",IF(IF(IF($A$24=B31,"R1-S1 (Rak1 kiri), ","")&IF($B$24=B31,"R1-S2 (Rak1 tengah), ","")&IF($C$24=B31,"R1-S3 (Rak1 kanan), ","")&IF($D$24=B31,"R2-S1 (Rak2 kiri), ","")&IF($E$24=B31,"R2-S2 (Rak2 tengah), ","")&IF($F$24=B31,"R2-S3 (Rak2 kanan), ","")&IF($G$24=B31,"R3-S1 (Rak3 kiri), ","")&IF($H$24=B31,"R3-S2 (Rak3 tengah), ","")&IF($I$24=B31,"R3-S3 (Rak3 kanan), ","")="","",IF(LEN(IF($A$24=B31,"R1-S1 (Rak1 kiri), ","")&IF($B$24=B31,"R1-S2 (Rak1 tengah), ","")&IF($C$24=B31,"R1-S3 (Rak1 kanan), ","")&IF($D$24=B31,"R2-S1 (Rak2 kiri), ","")&IF($E$24=B31,"R2-S2 (Rak2 tengah), ","")&IF($F$24=B31,"R2-S3 (Rak2 kanan), ","")&IF($G$24=B31,"R3-S1 (Rak3 kiri), ","")&IF($H$24=B31,"R3-S2 (Rak3 tengah), ","")&IF($I$24=B31,"R3-S3 (Rak3 kanan), ",""))>2,LEFT(IF($A$24=B31,"R1-S1 (Rak1 kiri), ","")&IF($B$24=B31,"R1-S2 (Rak1 tengah), ","")&IF($C$24=B31,"R1-S3 (Rak1 kanan), ","")&IF($D$24=B31,"R2-S1 (Rak2 kiri), ","")&IF($E$24=B31,"R2-S2 (Rak2 tengah), ","")&IF($F$24=B31,"R2-S3 (Rak2 kanan), ","")&IF($G$24=B31,"R3-S1 (Rak3 kiri), ","")&IF($H$24=B31,"R3-S2 (Rak3 tengah), ","")&IF($I$24=B31,"R3-S3 (Rak3 kanan), ",""),LEN(IF($A$24=B31,"R1-S1 (Rak1 kiri), ","")&IF($B$24=B31,"R1-S2 (Rak1 tengah), ","")&IF($C$24=B31,"R1-S3 (Rak1 kanan), ","")&IF($D$24=B31,"R2-S1 (Rak2 kiri), ","")&IF($E$24=B31,"R2-S2 (Rak2 tengah), ","")&IF($F$24=B31,"R2-S3 (Rak2 kanan), ","")&IF($G$24=B31,"R3-S1 (Rak3 kiri), ","")&IF($H$24=B31,"R3-S2 (Rak3 tengah), ","")&IF($I$24=B31,"R3-S3 (Rak3 kanan), ",""))-2),IF($A$24=B31,"R1-S1 (Rak1 kiri), ","")&IF($B$24=B31,"R1-S2 (Rak1 tengah), ","")&IF($C$24=B31,"R1-S3 (Rak1 kanan), ","")&IF($D$24=B31,"R2-S1 (Rak2 kiri), ","")&IF($E$24=B31,"R2-S2 (Rak2 tengah), ","")&IF($F$24=B31,"R2-S3 (Rak2 kanan), ","")&IF($G$24=B31,"R3-S1 (Rak3 kiri), ","")&IF($H$24=B31,"R3-S2 (Rak3 tengah), ","")&IF($I$24=B31,"R3-S3 (Rak3 kanan), ","")))="","","Slot marker "&B31&": "&IF(IF($A$24=B31,"R1-S1 (Rak1 kiri), ","")&IF($B$24=B31,"R1-S2 (Rak1 tengah), ","")&IF($C$24=B31,"R1-S3 (Rak1 kanan), ","")&IF($D$24=B31,"R2-S1 (Rak2 kiri), ","")&IF($E$24=B31,"R2-S2 (Rak2 tengah), ","")&IF($F$24=B31,"R2-S3 (Rak2 kanan), ","")&IF($G$24=B31,"R3-S1 (Rak3 kiri), ","")&IF($H$24=B31,"R3-S2 (Rak3 tengah), ","")&IF($I$24=B31,"R3-S3 (Rak3 kanan), ","")="","",IF(LEN(IF($A$24=B31,"R1-S1 (Rak1 kiri), ","")&IF($B$24=B31,"R1-S2 (Rak1 tengah), ","")&IF($C$24=B31,"R1-S3 (Rak1 kanan), ","")&IF($D$24=B31,"R2-S1 (Rak2 kiri), ","")&IF($E$24=B31,"R2-S2 (Rak2 tengah), ","")&IF($F$24=B31,"R2-S3 (Rak2 kanan), ","")&IF($G$24=B31,"R3-S1 (Rak3 kiri), ","")&IF($H$24=B31,"R3-S2 (Rak3 tengah), ","")&IF($I$24=B31,"R3-S3 (Rak3 kanan), ",""))>2,LEFT(IF($A$24=B31,"R1-S1 (Rak1 kiri), ","")&IF($B$24=B31,"R1-S2 (Rak1 tengah), ","")&IF($C$24=B31,"R1-S3 (Rak1 kanan), ","")&IF($D$24=B31,"R2-S1 (Rak2 kiri), ","")&IF($E$24=B31,"R2-S2 (Rak2 tengah), ","")&IF($F$24=B31,"R2-S3 (Rak2 kanan), ","")&IF($G$24=B31,"R3-S1 (Rak3 kiri), ","")&IF($H$24=B31,"R3-S2 (Rak3 tengah), ","")&IF($I$24=B31,"R3-S3 (Rak3 kanan), ",""),LEN(IF($A$24=B31,"R1-S1 (Rak1 kiri), ","")&IF($B$24=B31,"R1-S2 (Rak1 tengah), ","")&IF($C$24=B31,"R1-S3 (Rak1 kanan), ","")&IF($D$24=B31,"R2-S1 (Rak2 kiri), ","")&IF($E$24=B31,"R2-S2 (Rak2 tengah), ","")&IF($F$24=B31,"R2-S3 (Rak2 kanan), ","")&IF($G$24=B31,"R3-S1 (Rak3 kiri), ","")&IF($H$24=B31,"R3-S2 (Rak3 tengah), ","")&IF($I$24=B31,"R3-S3 (Rak3 kanan), ",""))-2),IF($A$24=B31,"R1-S1 (Rak1 kiri), ","")&IF($B$24=B31,"R1-S2 (Rak1 tengah), ","")&IF($C$24=B31,"R1-S3 (Rak1 kanan), ","")&IF($D$24=B31,"R2-S1 (Rak2 kiri), ","")&IF($E$24=B31,"R2-S2 (Rak2 tengah), ","")&IF($F$24=B31,"R2-S3 (Rak2 kanan), ","")&IF($G$24=B31,"R3-S1 (Rak3 kiri), ","")&IF($H$24=B31,"R3-S2 (Rak3 tengah), ","")&IF($I$24=B31,"R3-S3 (Rak3 kanan), ","")))))) | J31: =IF(G31="","",IF(G31=1,0,1))
A32: K-H2 | B32: =IF(A32="","",VLOOKUP(A32,'Undian Kubus'!$A$10:$D$18,2,FALSE)) | C32: =IF(A32="","",VLOOKUP(A32,'Undian Kubus'!$A$10:$D$18,3,FALSE)) | D32: =IF(A32="","",IF(E32="","(belum diisi — isi kolom E & F)",TRIM(E32&IF(F32<>""," — "&F32,"")))) | E32: Stand B | F32: depan | G32: =IF(OR(A32="",E32="",F32=""),"",IF(OR(AND(OR(E32="Rak 1",E32="R1"),OR(LOWER(F32)="kiri",LOWER(F32)="s1",LOWER(F32)="r1-s1"),$A$24=B32),AND(OR(E32="Rak 1",E32="R1"),OR(LOWER(F32)="tengah",LOWER(F32)="s2",LOWER(F32)="r1-s2"),$B$24=B32),AND(OR(E32="Rak 1",E32="R1"),OR(LOWER(F32)="kanan",LOWER(F32)="s3",LOWER(F32)="r1-s3"),$C$24=B32),AND(OR(E32="Rak 2",E32="R2"),OR(LOWER(F32)="kiri",LOWER(F32)="s1",LOWER(F32)="r2-s1"),$D$24=B32),AND(OR(E32="Rak 2",E32="R2"),OR(LOWER(F32)="tengah",LOWER(F32)="s2",LOWER(F32)="r2-s2"),$E$24=B32),AND(OR(E32="Rak 2",E32="R2"),OR(LOWER(F32)="kanan",LOWER(F32)="s3",LOWER(F32)="r2-s3"),$F$24=B32),AND(OR(E32="Rak 3",E32="R3"),OR(LOWER(F32)="kiri",LOWER(F32)="s1",LOWER(F32)="r3-s1"),$G$24=B32),AND(OR(E32="Rak 3",E32="R3"),OR(LOWER(F32)="tengah",LOWER(F32)="s2",LOWER(F32)="r3-s2"),$H$24=B32),AND(OR(E32="Rak 3",E32="R3"),OR(LOWER(F32)="kanan",LOWER(F32)="s3",LOWER(F32)="r3-s3"),$I$24=B32)),1,0)) | H32: =IF(B32="","",IF(COUNTA($A$24:$I$24)=0,"(isi warna marker baris 24)",IF(IF(COUNTIF($A$24:$C$24,B32)>0,"Rak 1, ","")&IF(COUNTIF($D$24:$F$24,B32)>0,"Rak 2, ","")&IF(COUNTIF($G$24:$I$24,B32)>0,"Rak 3, ","")="","",IF(LEN(IF(COUNTIF($A$24:$C$24,B32)>0,"Rak 1, ","")&IF(COUNTIF($D$24:$F$24,B32)>0,"Rak 2, ","")&IF(COUNTIF($G$24:$I$24,B32)>0,"Rak 3, ",""))>2,LEFT(IF(COUNTIF($A$24:$C$24,B32)>0,"Rak 1, ","")&IF(COUNTIF($D$24:$F$24,B32)>0,"Rak 2, ","")&IF(COUNTIF($G$24:$I$24,B32)>0,"Rak 3, ",""),LEN(IF(COUNTIF($A$24:$C$24,B32)>0,"Rak 1, ","")&IF(COUNTIF($D$24:$F$24,B32)>0,"Rak 2, ","")&IF(COUNTIF($G$24:$I$24,B32)>0,"Rak 3, ",""))-2),IF(COUNTIF($A$24:$C$24,B32)>0,"Rak 1, ","")&IF(COUNTIF($D$24:$F$24,B32)>0,"Rak 2, ","")&IF(COUNTIF($G$24:$I$24,B32)>0,"Rak 3, ",""))))) | I32: =IF(B32="","",IF(COUNTA($A$24:$I$24)=0,"(isi warna marker baris 24)",IF(IF(IF($A$24=B32,"R1-S1 (Rak1 kiri), ","")&IF($B$24=B32,"R1-S2 (Rak1 tengah), ","")&IF($C$24=B32,"R1-S3 (Rak1 kanan), ","")&IF($D$24=B32,"R2-S1 (Rak2 kiri), ","")&IF($E$24=B32,"R2-S2 (Rak2 tengah), ","")&IF($F$24=B32,"R2-S3 (Rak2 kanan), ","")&IF($G$24=B32,"R3-S1 (Rak3 kiri), ","")&IF($H$24=B32,"R3-S2 (Rak3 tengah), ","")&IF($I$24=B32,"R3-S3 (Rak3 kanan), ","")="","",IF(LEN(IF($A$24=B32,"R1-S1 (Rak1 kiri), ","")&IF($B$24=B32,"R1-S2 (Rak1 tengah), ","")&IF($C$24=B32,"R1-S3 (Rak1 kanan), ","")&IF($D$24=B32,"R2-S1 (Rak2 kiri), ","")&IF($E$24=B32,"R2-S2 (Rak2 tengah), ","")&IF($F$24=B32,"R2-S3 (Rak2 kanan), ","")&IF($G$24=B32,"R3-S1 (Rak3 kiri), ","")&IF($H$24=B32,"R3-S2 (Rak3 tengah), ","")&IF($I$24=B32,"R3-S3 (Rak3 kanan), ",""))>2,LEFT(IF($A$24=B32,"R1-S1 (Rak1 kiri), ","")&IF($B$24=B32,"R1-S2 (Rak1 tengah), ","")&IF($C$24=B32,"R1-S3 (Rak1 kanan), ","")&IF($D$24=B32,"R2-S1 (Rak2 kiri), ","")&IF($E$24=B32,"R2-S2 (Rak2 tengah), ","")&IF($F$24=B32,"R2-S3 (Rak2 kanan), ","")&IF($G$24=B32,"R3-S1 (Rak3 kiri), ","")&IF($H$24=B32,"R3-S2 (Rak3 tengah), ","")&IF($I$24=B32,"R3-S3 (Rak3 kanan), ",""),LEN(IF($A$24=B32,"R1-S1 (Rak1 kiri), ","")&IF($B$24=B32,"R1-S2 (Rak1 tengah), ","")&IF($C$24=B32,"R1-S3 (Rak1 kanan), ","")&IF($D$24=B32,"R2-S1 (Rak2 kiri), ","")&IF($E$24=B32,"R2-S2 (Rak2 tengah), ","")&IF($F$24=B32,"R2-S3 (Rak2 kanan), ","")&IF($G$24=B32,"R3-S1 (Rak3 kiri), ","")&IF($H$24=B32,"R3-S2 (Rak3 tengah), ","")&IF($I$24=B32,"R3-S3 (Rak3 kanan), ",""))-2),IF($A$24=B32,"R1-S1 (Rak1 kiri), ","")&IF($B$24=B32,"R1-S2 (Rak1 tengah), ","")&IF($C$24=B32,"R1-S3 (Rak1 kanan), ","")&IF($D$24=B32,"R2-S1 (Rak2 kiri), ","")&IF($E$24=B32,"R2-S2 (Rak2 tengah), ","")&IF($F$24=B32,"R2-S3 (Rak2 kanan), ","")&IF($G$24=B32,"R3-S1 (Rak3 kiri), ","")&IF($H$24=B32,"R3-S2 (Rak3 tengah), ","")&IF($I$24=B32,"R3-S3 (Rak3 kanan), ","")))="","","Slot marker "&B32&": "&IF(IF($A$24=B32,"R1-S1 (Rak1 kiri), ","")&IF($B$24=B32,"R1-S2 (Rak1 tengah), ","")&IF($C$24=B32,"R1-S3 (Rak1 kanan), ","")&IF($D$24=B32,"R2-S1 (Rak2 kiri), ","")&IF($E$24=B32,"R2-S2 (Rak2 tengah), ","")&IF($F$24=B32,"R2-S3 (Rak2 kanan), ","")&IF($G$24=B32,"R3-S1 (Rak3 kiri), ","")&IF($H$24=B32,"R3-S2 (Rak3 tengah), ","")&IF($I$24=B32,"R3-S3 (Rak3 kanan), ","")="","",IF(LEN(IF($A$24=B32,"R1-S1 (Rak1 kiri), ","")&IF($B$24=B32,"R1-S2 (Rak1 tengah), ","")&IF($C$24=B32,"R1-S3 (Rak1 kanan), ","")&IF($D$24=B32,"R2-S1 (Rak2 kiri), ","")&IF($E$24=B32,"R2-S2 (Rak2 tengah), ","")&IF($F$24=B32,"R2-S3 (Rak2 kanan), ","")&IF($G$24=B32,"R3-S1 (Rak3 kiri), ","")&IF($H$24=B32,"R3-S2 (Rak3 tengah), ","")&IF($I$24=B32,"R3-S3 (Rak3 kanan), ",""))>2,LEFT(IF($A$24=B32,"R1-S1 (Rak1 kiri), ","")&IF($B$24=B32,"R1-S2 (Rak1 tengah), ","")&IF($C$24=B32,"R1-S3 (Rak1 kanan), ","")&IF($D$24=B32,"R2-S1 (Rak2 kiri), ","")&IF($E$24=B32,"R2-S2 (Rak2 tengah), ","")&IF($F$24=B32,"R2-S3 (Rak2 kanan), ","")&IF($G$24=B32,"R3-S1 (Rak3 kiri), ","")&IF($H$24=B32,"R3-S2 (Rak3 tengah), ","")&IF($I$24=B32,"R3-S3 (Rak3 kanan), ",""),LEN(IF($A$24=B32,"R1-S1 (Rak1 kiri), ","")&IF($B$24=B32,"R1-S2 (Rak1 tengah), ","")&IF($C$24=B32,"R1-S3 (Rak1 kanan), ","")&IF($D$24=B32,"R2-S1 (Rak2 kiri), ","")&IF($E$24=B32,"R2-S2 (Rak2 tengah), ","")&IF($F$24=B32,"R2-S3 (Rak2 kanan), ","")&IF($G$24=B32,"R3-S1 (Rak3 kiri), ","")&IF($H$24=B32,"R3-S2 (Rak3 tengah), ","")&IF($I$24=B32,"R3-S3 (Rak3 kanan), ",""))-2),IF($A$24=B32,"R1-S1 (Rak1 kiri), ","")&IF($B$24=B32,"R1-S2 (Rak1 tengah), ","")&IF($C$24=B32,"R1-S3 (Rak1 kanan), ","")&IF($D$24=B32,"R2-S1 (Rak2 kiri), ","")&IF($E$24=B32,"R2-S2 (Rak2 tengah), ","")&IF($F$24=B32,"R2-S3 (Rak2 kanan), ","")&IF($G$24=B32,"R3-S1 (Rak3 kiri), ","")&IF($H$24=B32,"R3-S2 (Rak3 tengah), ","")&IF($I$24=B32,"R3-S3 (Rak3 kanan), ","")))))) | J32: =IF(G32="","",IF(G32=1,0,1))
A33: K-H3 | B33: =IF(A33="","",VLOOKUP(A33,'Undian Kubus'!$A$10:$D$18,2,FALSE)) | C33: =IF(A33="","",VLOOKUP(A33,'Undian Kubus'!$A$10:$D$18,3,FALSE)) | D33: =IF(A33="","",IF(E33="","(belum diisi — isi kolom E & F)",TRIM(E33&IF(F33<>""," — "&F33,"")))) | E33: Rak 1 | F33: kanan | G33: =IF(OR(A33="",E33="",F33=""),"",IF(OR(AND(OR(E33="Rak 1",E33="R1"),OR(LOWER(F33)="kiri",LOWER(F33)="s1",LOWER(F33)="r1-s1"),$A$24=B33),AND(OR(E33="Rak 1",E33="R1"),OR(LOWER(F33)="tengah",LOWER(F33)="s2",LOWER(F33)="r1-s2"),$B$24=B33),AND(OR(E33="Rak 1",E33="R1"),OR(LOWER(F33)="kanan",LOWER(F33)="s3",LOWER(F33)="r1-s3"),$C$24=B33),AND(OR(E33="Rak 2",E33="R2"),OR(LOWER(F33)="kiri",LOWER(F33)="s1",LOWER(F33)="r2-s1"),$D$24=B33),AND(OR(E33="Rak 2",E33="R2"),OR(LOWER(F33)="tengah",LOWER(F33)="s2",LOWER(F33)="r2-s2"),$E$24=B33),AND(OR(E33="Rak 2",E33="R2"),OR(LOWER(F33)="kanan",LOWER(F33)="s3",LOWER(F33)="r2-s3"),$F$24=B33),AND(OR(E33="Rak 3",E33="R3"),OR(LOWER(F33)="kiri",LOWER(F33)="s1",LOWER(F33)="r3-s1"),$G$24=B33),AND(OR(E33="Rak 3",E33="R3"),OR(LOWER(F33)="tengah",LOWER(F33)="s2",LOWER(F33)="r3-s2"),$H$24=B33),AND(OR(E33="Rak 3",E33="R3"),OR(LOWER(F33)="kanan",LOWER(F33)="s3",LOWER(F33)="r3-s3"),$I$24=B33)),1,0)) | H33: =IF(B33="","",IF(COUNTA($A$24:$I$24)=0,"(isi warna marker baris 24)",IF(IF(COUNTIF($A$24:$C$24,B33)>0,"Rak 1, ","")&IF(COUNTIF($D$24:$F$24,B33)>0,"Rak 2, ","")&IF(COUNTIF($G$24:$I$24,B33)>0,"Rak 3, ","")="","",IF(LEN(IF(COUNTIF($A$24:$C$24,B33)>0,"Rak 1, ","")&IF(COUNTIF($D$24:$F$24,B33)>0,"Rak 2, ","")&IF(COUNTIF($G$24:$I$24,B33)>0,"Rak 3, ",""))>2,LEFT(IF(COUNTIF($A$24:$C$24,B33)>0,"Rak 1, ","")&IF(COUNTIF($D$24:$F$24,B33)>0,"Rak 2, ","")&IF(COUNTIF($G$24:$I$24,B33)>0,"Rak 3, ",""),LEN(IF(COUNTIF($A$24:$C$24,B33)>0,"Rak 1, ","")&IF(COUNTIF($D$24:$F$24,B33)>0,"Rak 2, ","")&IF(COUNTIF($G$24:$I$24,B33)>0,"Rak 3, ",""))-2),IF(COUNTIF($A$24:$C$24,B33)>0,"Rak 1, ","")&IF(COUNTIF($D$24:$F$24,B33)>0,"Rak 2, ","")&IF(COUNTIF($G$24:$I$24,B33)>0,"Rak 3, ",""))))) | I33: =IF(B33="","",IF(COUNTA($A$24:$I$24)=0,"(isi warna marker baris 24)",IF(IF(IF($A$24=B33,"R1-S1 (Rak1 kiri), ","")&IF($B$24=B33,"R1-S2 (Rak1 tengah), ","")&IF($C$24=B33,"R1-S3 (Rak1 kanan), ","")&IF($D$24=B33,"R2-S1 (Rak2 kiri), ","")&IF($E$24=B33,"R2-S2 (Rak2 tengah), ","")&IF($F$24=B33,"R2-S3 (Rak2 kanan), ","")&IF($G$24=B33,"R3-S1 (Rak3 kiri), ","")&IF($H$24=B33,"R3-S2 (Rak3 tengah), ","")&IF($I$24=B33,"R3-S3 (Rak3 kanan), ","")="","",IF(LEN(IF($A$24=B33,"R1-S1 (Rak1 kiri), ","")&IF($B$24=B33,"R1-S2 (Rak1 tengah), ","")&IF($C$24=B33,"R1-S3 (Rak1 kanan), ","")&IF($D$24=B33,"R2-S1 (Rak2 kiri), ","")&IF($E$24=B33,"R2-S2 (Rak2 tengah), ","")&IF($F$24=B33,"R2-S3 (Rak2 kanan), ","")&IF($G$24=B33,"R3-S1 (Rak3 kiri), ","")&IF($H$24=B33,"R3-S2 (Rak3 tengah), ","")&IF($I$24=B33,"R3-S3 (Rak3 kanan), ",""))>2,LEFT(IF($A$24=B33,"R1-S1 (Rak1 kiri), ","")&IF($B$24=B33,"R1-S2 (Rak1 tengah), ","")&IF($C$24=B33,"R1-S3 (Rak1 kanan), ","")&IF($D$24=B33,"R2-S1 (Rak2 kiri), ","")&IF($E$24=B33,"R2-S2 (Rak2 tengah), ","")&IF($F$24=B33,"R2-S3 (Rak2 kanan), ","")&IF($G$24=B33,"R3-S1 (Rak3 kiri), ","")&IF($H$24=B33,"R3-S2 (Rak3 tengah), ","")&IF($I$24=B33,"R3-S3 (Rak3 kanan), ",""),LEN(IF($A$24=B33,"R1-S1 (Rak1 kiri), ","")&IF($B$24=B33,"R1-S2 (Rak1 tengah), ","")&IF($C$24=B33,"R1-S3 (Rak1 kanan), ","")&IF($D$24=B33,"R2-S1 (Rak2 kiri), ","")&IF($E$24=B33,"R2-S2 (Rak2 tengah), ","")&IF($F$24=B33,"R2-S3 (Rak2 kanan), ","")&IF($G$24=B33,"R3-S1 (Rak3 kiri), ","")&IF($H$24=B33,"R3-S2 (Rak3 tengah), ","")&IF($I$24=B33,"R3-S3 (Rak3 kanan), ",""))-2),IF($A$24=B33,"R1-S1 (Rak1 kiri), ","")&IF($B$24=B33,"R1-S2 (Rak1 tengah), ","")&IF($C$24=B33,"R1-S3 (Rak1 kanan), ","")&IF($D$24=B33,"R2-S1 (Rak2 kiri), ","")&IF($E$24=B33,"R2-S2 (Rak2 tengah), ","")&IF($F$24=B33,"R2-S3 (Rak2 kanan), ","")&IF($G$24=B33,"R3-S1 (Rak3 kiri), ","")&IF($H$24=B33,"R3-S2 (Rak3 tengah), ","")&IF($I$24=B33,"R3-S3 (Rak3 kanan), ","")))="","","Slot marker "&B33&": "&IF(IF($A$24=B33,"R1-S1 (Rak1 kiri), ","")&IF($B$24=B33,"R1-S2 (Rak1 tengah), ","")&IF($C$24=B33,"R1-S3 (Rak1 kanan), ","")&IF($D$24=B33,"R2-S1 (Rak2 kiri), ","")&IF($E$24=B33,"R2-S2 (Rak2 tengah), ","")&IF($F$24=B33,"R2-S3 (Rak2 kanan), ","")&IF($G$24=B33,"R3-S1 (Rak3 kiri), ","")&IF($H$24=B33,"R3-S2 (Rak3 tengah), ","")&IF($I$24=B33,"R3-S3 (Rak3 kanan), ","")="","",IF(LEN(IF($A$24=B33,"R1-S1 (Rak1 kiri), ","")&IF($B$24=B33,"R1-S2 (Rak1 tengah), ","")&IF($C$24=B33,"R1-S3 (Rak1 kanan), ","")&IF($D$24=B33,"R2-S1 (Rak2 kiri), ","")&IF($E$24=B33,"R2-S2 (Rak2 tengah), ","")&IF($F$24=B33,"R2-S3 (Rak2 kanan), ","")&IF($G$24=B33,"R3-S1 (Rak3 kiri), ","")&IF($H$24=B33,"R3-S2 (Rak3 tengah), ","")&IF($I$24=B33,"R3-S3 (Rak3 kanan), ",""))>2,LEFT(IF($A$24=B33,"R1-S1 (Rak1 kiri), ","")&IF($B$24=B33,"R1-S2 (Rak1 tengah), ","")&IF($C$24=B33,"R1-S3 (Rak1 kanan), ","")&IF($D$24=B33,"R2-S1 (Rak2 kiri), ","")&IF($E$24=B33,"R2-S2 (Rak2 tengah), ","")&IF($F$24=B33,"R2-S3 (Rak2 kanan), ","")&IF($G$24=B33,"R3-S1 (Rak3 kiri), ","")&IF($H$24=B33,"R3-S2 (Rak3 tengah), ","")&IF($I$24=B33,"R3-S3 (Rak3 kanan), ",""),LEN(IF($A$24=B33,"R1-S1 (Rak1 kiri), ","")&IF($B$24=B33,"R1-S2 (Rak1 tengah), ","")&IF($C$24=B33,"R1-S3 (Rak1 kanan), ","")&IF($D$24=B33,"R2-S1 (Rak2 kiri), ","")&IF($E$24=B33,"R2-S2 (Rak2 tengah), ","")&IF($F$24=B33,"R2-S3 (Rak2 kanan), ","")&IF($G$24=B33,"R3-S1 (Rak3 kiri), ","")&IF($H$24=B33,"R3-S2 (Rak3 tengah), ","")&IF($I$24=B33,"R3-S3 (Rak3 kanan), ",""))-2),IF($A$24=B33,"R1-S1 (Rak1 kiri), ","")&IF($B$24=B33,"R1-S2 (Rak1 tengah), ","")&IF($C$24=B33,"R1-S3 (Rak1 kanan), ","")&IF($D$24=B33,"R2-S1 (Rak2 kiri), ","")&IF($E$24=B33,"R2-S2 (Rak2 tengah), ","")&IF($F$24=B33,"R2-S3 (Rak2 kanan), ","")&IF($G$24=B33,"R3-S1 (Rak3 kiri), ","")&IF($H$24=B33,"R3-S2 (Rak3 tengah), ","")&IF($I$24=B33,"R3-S3 (Rak3 kanan), ","")))))) | J33: =IF(G33="","",IF(G33=1,0,1))
A34: K-B1 | B34: =IF(A34="","",VLOOKUP(A34,'Undian Kubus'!$A$10:$D$18,2,FALSE)) | C34: =IF(A34="","",VLOOKUP(A34,'Undian Kubus'!$A$10:$D$18,3,FALSE)) | D34: =IF(A34="","",IF(E34="","(belum diisi — isi kolom E & F)",TRIM(E34&IF(F34<>""," — "&F34,"")))) | E34: Rak 2 | F34: kiri | G34: =IF(OR(A34="",E34="",F34=""),"",IF(OR(AND(OR(E34="Rak 1",E34="R1"),OR(LOWER(F34)="kiri",LOWER(F34)="s1",LOWER(F34)="r1-s1"),$A$24=B34),AND(OR(E34="Rak 1",E34="R1"),OR(LOWER(F34)="tengah",LOWER(F34)="s2",LOWER(F34)="r1-s2"),$B$24=B34),AND(OR(E34="Rak 1",E34="R1"),OR(LOWER(F34)="kanan",LOWER(F34)="s3",LOWER(F34)="r1-s3"),$C$24=B34),AND(OR(E34="Rak 2",E34="R2"),OR(LOWER(F34)="kiri",LOWER(F34)="s1",LOWER(F34)="r2-s1"),$D$24=B34),AND(OR(E34="Rak 2",E34="R2"),OR(LOWER(F34)="tengah",LOWER(F34)="s2",LOWER(F34)="r2-s2"),$E$24=B34),AND(OR(E34="Rak 2",E34="R2"),OR(LOWER(F34)="kanan",LOWER(F34)="s3",LOWER(F34)="r2-s3"),$F$24=B34),AND(OR(E34="Rak 3",E34="R3"),OR(LOWER(F34)="kiri",LOWER(F34)="s1",LOWER(F34)="r3-s1"),$G$24=B34),AND(OR(E34="Rak 3",E34="R3"),OR(LOWER(F34)="tengah",LOWER(F34)="s2",LOWER(F34)="r3-s2"),$H$24=B34),AND(OR(E34="Rak 3",E34="R3"),OR(LOWER(F34)="kanan",LOWER(F34)="s3",LOWER(F34)="r3-s3"),$I$24=B34)),1,0)) | H34: =IF(B34="","",IF(COUNTA($A$24:$I$24)=0,"(isi warna marker baris 24)",IF(IF(COUNTIF($A$24:$C$24,B34)>0,"Rak 1, ","")&IF(COUNTIF($D$24:$F$24,B34)>0,"Rak 2, ","")&IF(COUNTIF($G$24:$I$24,B34)>0,"Rak 3, ","")="","",IF(LEN(IF(COUNTIF($A$24:$C$24,B34)>0,"Rak 1, ","")&IF(COUNTIF($D$24:$F$24,B34)>0,"Rak 2, ","")&IF(COUNTIF($G$24:$I$24,B34)>0,"Rak 3, ",""))>2,LEFT(IF(COUNTIF($A$24:$C$24,B34)>0,"Rak 1, ","")&IF(COUNTIF($D$24:$F$24,B34)>0,"Rak 2, ","")&IF(COUNTIF($G$24:$I$24,B34)>0,"Rak 3, ",""),LEN(IF(COUNTIF($A$24:$C$24,B34)>0,"Rak 1, ","")&IF(COUNTIF($D$24:$F$24,B34)>0,"Rak 2, ","")&IF(COUNTIF($G$24:$I$24,B34)>0,"Rak 3, ",""))-2),IF(COUNTIF($A$24:$C$24,B34)>0,"Rak 1, ","")&IF(COUNTIF($D$24:$F$24,B34)>0,"Rak 2, ","")&IF(COUNTIF($G$24:$I$24,B34)>0,"Rak 3, ",""))))) | I34: =IF(B34="","",IF(COUNTA($A$24:$I$24)=0,"(isi warna marker baris 24)",IF(IF(IF($A$24=B34,"R1-S1 (Rak1 kiri), ","")&IF($B$24=B34,"R1-S2 (Rak1 tengah), ","")&IF($C$24=B34,"R1-S3 (Rak1 kanan), ","")&IF($D$24=B34,"R2-S1 (Rak2 kiri), ","")&IF($E$24=B34,"R2-S2 (Rak2 tengah), ","")&IF($F$24=B34,"R2-S3 (Rak2 kanan), ","")&IF($G$24=B34,"R3-S1 (Rak3 kiri), ","")&IF($H$24=B34,"R3-S2 (Rak3 tengah), ","")&IF($I$24=B34,"R3-S3 (Rak3 kanan), ","")="","",IF(LEN(IF($A$24=B34,"R1-S1 (Rak1 kiri), ","")&IF($B$24=B34,"R1-S2 (Rak1 tengah), ","")&IF($C$24=B34,"R1-S3 (Rak1 kanan), ","")&IF($D$24=B34,"R2-S1 (Rak2 kiri), ","")&IF($E$24=B34,"R2-S2 (Rak2 tengah), ","")&IF($F$24=B34,"R2-S3 (Rak2 kanan), ","")&IF($G$24=B34,"R3-S1 (Rak3 kiri), ","")&IF($H$24=B34,"R3-S2 (Rak3 tengah), ","")&IF($I$24=B34,"R3-S3 (Rak3 kanan), ",""))>2,LEFT(IF($A$24=B34,"R1-S1 (Rak1 kiri), ","")&IF($B$24=B34,"R1-S2 (Rak1 tengah), ","")&IF($C$24=B34,"R1-S3 (Rak1 kanan), ","")&IF($D$24=B34,"R2-S1 (Rak2 kiri), ","")&IF($E$24=B34,"R2-S2 (Rak2 tengah), ","")&IF($F$24=B34,"R2-S3 (Rak2 kanan), ","")&IF($G$24=B34,"R3-S1 (Rak3 kiri), ","")&IF($H$24=B34,"R3-S2 (Rak3 tengah), ","")&IF($I$24=B34,"R3-S3 (Rak3 kanan), ",""),LEN(IF($A$24=B34,"R1-S1 (Rak1 kiri), ","")&IF($B$24=B34,"R1-S2 (Rak1 tengah), ","")&IF($C$24=B34,"R1-S3 (Rak1 kanan), ","")&IF($D$24=B34,"R2-S1 (Rak2 kiri), ","")&IF($E$24=B34,"R2-S2 (Rak2 tengah), ","")&IF($F$24=B34,"R2-S3 (Rak2 kanan), ","")&IF($G$24=B34,"R3-S1 (Rak3 kiri), ","")&IF($H$24=B34,"R3-S2 (Rak3 tengah), ","")&IF($I$24=B34,"R3-S3 (Rak3 kanan), ",""))-2),IF($A$24=B34,"R1-S1 (Rak1 kiri), ","")&IF($B$24=B34,"R1-S2 (Rak1 tengah), ","")&IF($C$24=B34,"R1-S3 (Rak1 kanan), ","")&IF($D$24=B34,"R2-S1 (Rak2 kiri), ","")&IF($E$24=B34,"R2-S2 (Rak2 tengah), ","")&IF($F$24=B34,"R2-S3 (Rak2 kanan), ","")&IF($G$24=B34,"R3-S1 (Rak3 kiri), ","")&IF($H$24=B34,"R3-S2 (Rak3 tengah), ","")&IF($I$24=B34,"R3-S3 (Rak3 kanan), ","")))="","","Slot marker "&B34&": "&IF(IF($A$24=B34,"R1-S1 (Rak1 kiri), ","")&IF($B$24=B34,"R1-S2 (Rak1 tengah), ","")&IF($C$24=B34,"R1-S3 (Rak1 kanan), ","")&IF($D$24=B34,"R2-S1 (Rak2 kiri), ","")&IF($E$24=B34,"R2-S2 (Rak2 tengah), ","")&IF($F$24=B34,"R2-S3 (Rak2 kanan), ","")&IF($G$24=B34,"R3-S1 (Rak3 kiri), ","")&IF($H$24=B34,"R3-S2 (Rak3 tengah), ","")&IF($I$24=B34,"R3-S3 (Rak3 kanan), ","")="","",IF(LEN(IF($A$24=B34,"R1-S1 (Rak1 kiri), ","")&IF($B$24=B34,"R1-S2 (Rak1 tengah), ","")&IF($C$24=B34,"R1-S3 (Rak1 kanan), ","")&IF($D$24=B34,"R2-S1 (Rak2 kiri), ","")&IF($E$24=B34,"R2-S2 (Rak2 tengah), ","")&IF($F$24=B34,"R2-S3 (Rak2 kanan), ","")&IF($G$24=B34,"R3-S1 (Rak3 kiri), ","")&IF($H$24=B34,"R3-S2 (Rak3 tengah), ","")&IF($I$24=B34,"R3-S3 (Rak3 kanan), ",""))>2,LEFT(IF($A$24=B34,"R1-S1 (Rak1 kiri), ","")&IF($B$24=B34,"R1-S2 (Rak1 tengah), ","")&IF($C$24=B34,"R1-S3 (Rak1 kanan), ","")&IF($D$24=B34,"R2-S1 (Rak2 kiri), ","")&IF($E$24=B34,"R2-S2 (Rak2 tengah), ","")&IF($F$24=B34,"R2-S3 (Rak2 kanan), ","")&IF($G$24=B34,"R3-S1 (Rak3 kiri), ","")&IF($H$24=B34,"R3-S2 (Rak3 tengah), ","")&IF($I$24=B34,"R3-S3 (Rak3 kanan), ",""),LEN(IF($A$24=B34,"R1-S1 (Rak1 kiri), ","")&IF($B$24=B34,"R1-S2 (Rak1 tengah), ","")&IF($C$24=B34,"R1-S3 (Rak1 kanan), ","")&IF($D$24=B34,"R2-S1 (Rak2 kiri), ","")&IF($E$24=B34,"R2-S2 (Rak2 tengah), ","")&IF($F$24=B34,"R2-S3 (Rak2 kanan), ","")&IF($G$24=B34,"R3-S1 (Rak3 kiri), ","")&IF($H$24=B34,"R3-S2 (Rak3 tengah), ","")&IF($I$24=B34,"R3-S3 (Rak3 kanan), ",""))-2),IF($A$24=B34,"R1-S1 (Rak1 kiri), ","")&IF($B$24=B34,"R1-S2 (Rak1 tengah), ","")&IF($C$24=B34,"R1-S3 (Rak1 kanan), ","")&IF($D$24=B34,"R2-S1 (Rak2 kiri), ","")&IF($E$24=B34,"R2-S2 (Rak2 tengah), ","")&IF($F$24=B34,"R2-S3 (Rak2 kanan), ","")&IF($G$24=B34,"R3-S1 (Rak3 kiri), ","")&IF($H$24=B34,"R3-S2 (Rak3 tengah), ","")&IF($I$24=B34,"R3-S3 (Rak3 kanan), ","")))))) | J34: =IF(G34="","",IF(G34=1,0,1))
A35: K-B2 | B35: =IF(A35="","",VLOOKUP(A35,'Undian Kubus'!$A$10:$D$18,2,FALSE)) | C35: =IF(A35="","",VLOOKUP(A35,'Undian Kubus'!$A$10:$D$18,3,FALSE)) | D35: =IF(A35="","",IF(E35="","(belum diisi — isi kolom E & F)",TRIM(E35&IF(F35<>""," — "&F35,"")))) | E35: Rak 3 | F35: tengah | G35: =IF(OR(A35="",E35="",F35=""),"",IF(OR(AND(OR(E35="Rak 1",E35="R1"),OR(LOWER(F35)="kiri",LOWER(F35)="s1",LOWER(F35)="r1-s1"),$A$24=B35),AND(OR(E35="Rak 1",E35="R1"),OR(LOWER(F35)="tengah",LOWER(F35)="s2",LOWER(F35)="r1-s2"),$B$24=B35),AND(OR(E35="Rak 1",E35="R1"),OR(LOWER(F35)="kanan",LOWER(F35)="s3",LOWER(F35)="r1-s3"),$C$24=B35),AND(OR(E35="Rak 2",E35="R2"),OR(LOWER(F35)="kiri",LOWER(F35)="s1",LOWER(F35)="r2-s1"),$D$24=B35),AND(OR(E35="Rak 2",E35="R2"),OR(LOWER(F35)="tengah",LOWER(F35)="s2",LOWER(F35)="r2-s2"),$E$24=B35),AND(OR(E35="Rak 2",E35="R2"),OR(LOWER(F35)="kanan",LOWER(F35)="s3",LOWER(F35)="r2-s3"),$F$24=B35),AND(OR(E35="Rak 3",E35="R3"),OR(LOWER(F35)="kiri",LOWER(F35)="s1",LOWER(F35)="r3-s1"),$G$24=B35),AND(OR(E35="Rak 3",E35="R3"),OR(LOWER(F35)="tengah",LOWER(F35)="s2",LOWER(F35)="r3-s2"),$H$24=B35),AND(OR(E35="Rak 3",E35="R3"),OR(LOWER(F35)="kanan",LOWER(F35)="s3",LOWER(F35)="r3-s3"),$I$24=B35)),1,0)) | H35: =IF(B35="","",IF(COUNTA($A$24:$I$24)=0,"(isi warna marker baris 24)",IF(IF(COUNTIF($A$24:$C$24,B35)>0,"Rak 1, ","")&IF(COUNTIF($D$24:$F$24,B35)>0,"Rak 2, ","")&IF(COUNTIF($G$24:$I$24,B35)>0,"Rak 3, ","")="","",IF(LEN(IF(COUNTIF($A$24:$C$24,B35)>0,"Rak 1, ","")&IF(COUNTIF($D$24:$F$24,B35)>0,"Rak 2, ","")&IF(COUNTIF($G$24:$I$24,B35)>0,"Rak 3, ",""))>2,LEFT(IF(COUNTIF($A$24:$C$24,B35)>0,"Rak 1, ","")&IF(COUNTIF($D$24:$F$24,B35)>0,"Rak 2, ","")&IF(COUNTIF($G$24:$I$24,B35)>0,"Rak 3, ",""),LEN(IF(COUNTIF($A$24:$C$24,B35)>0,"Rak 1, ","")&IF(COUNTIF($D$24:$F$24,B35)>0,"Rak 2, ","")&IF(COUNTIF($G$24:$I$24,B35)>0,"Rak 3, ",""))-2),IF(COUNTIF($A$24:$C$24,B35)>0,"Rak 1, ","")&IF(COUNTIF($D$24:$F$24,B35)>0,"Rak 2, ","")&IF(COUNTIF($G$24:$I$24,B35)>0,"Rak 3, ",""))))) | I35: =IF(B35="","",IF(COUNTA($A$24:$I$24)=0,"(isi warna marker baris 24)",IF(IF(IF($A$24=B35,"R1-S1 (Rak1 kiri), ","")&IF($B$24=B35,"R1-S2 (Rak1 tengah), ","")&IF($C$24=B35,"R1-S3 (Rak1 kanan), ","")&IF($D$24=B35,"R2-S1 (Rak2 kiri), ","")&IF($E$24=B35,"R2-S2 (Rak2 tengah), ","")&IF($F$24=B35,"R2-S3 (Rak2 kanan), ","")&IF($G$24=B35,"R3-S1 (Rak3 kiri), ","")&IF($H$24=B35,"R3-S2 (Rak3 tengah), ","")&IF($I$24=B35,"R3-S3 (Rak3 kanan), ","")="","",IF(LEN(IF($A$24=B35,"R1-S1 (Rak1 kiri), ","")&IF($B$24=B35,"R1-S2 (Rak1 tengah), ","")&IF($C$24=B35,"R1-S3 (Rak1 kanan), ","")&IF($D$24=B35,"R2-S1 (Rak2 kiri), ","")&IF($E$24=B35,"R2-S2 (Rak2 tengah), ","")&IF($F$24=B35,"R2-S3 (Rak2 kanan), ","")&IF($G$24=B35,"R3-S1 (Rak3 kiri), ","")&IF($H$24=B35,"R3-S2 (Rak3 tengah), ","")&IF($I$24=B35,"R3-S3 (Rak3 kanan), ",""))>2,LEFT(IF($A$24=B35,"R1-S1 (Rak1 kiri), ","")&IF($B$24=B35,"R1-S2 (Rak1 tengah), ","")&IF($C$24=B35,"R1-S3 (Rak1 kanan), ","")&IF($D$24=B35,"R2-S1 (Rak2 kiri), ","")&IF($E$24=B35,"R2-S2 (Rak2 tengah), ","")&IF($F$24=B35,"R2-S3 (Rak2 kanan), ","")&IF($G$24=B35,"R3-S1 (Rak3 kiri), ","")&IF($H$24=B35,"R3-S2 (Rak3 tengah), ","")&IF($I$24=B35,"R3-S3 (Rak3 kanan), ",""),LEN(IF($A$24=B35,"R1-S1 (Rak1 kiri), ","")&IF($B$24=B35,"R1-S2 (Rak1 tengah), ","")&IF($C$24=B35,"R1-S3 (Rak1 kanan), ","")&IF($D$24=B35,"R2-S1 (Rak2 kiri), ","")&IF($E$24=B35,"R2-S2 (Rak2 tengah), ","")&IF($F$24=B35,"R2-S3 (Rak2 kanan), ","")&IF($G$24=B35,"R3-S1 (Rak3 kiri), ","")&IF($H$24=B35,"R3-S2 (Rak3 tengah), ","")&IF($I$24=B35,"R3-S3 (Rak3 kanan), ",""))-2),IF($A$24=B35,"R1-S1 (Rak1 kiri), ","")&IF($B$24=B35,"R1-S2 (Rak1 tengah), ","")&IF($C$24=B35,"R1-S3 (Rak1 kanan), ","")&IF($D$24=B35,"R2-S1 (Rak2 kiri), ","")&IF($E$24=B35,"R2-S2 (Rak2 tengah), ","")&IF($F$24=B35,"R2-S3 (Rak2 kanan), ","")&IF($G$24=B35,"R3-S1 (Rak3 kiri), ","")&IF($H$24=B35,"R3-S2 (Rak3 tengah), ","")&IF($I$24=B35,"R3-S3 (Rak3 kanan), ","")))="","","Slot marker "&B35&": "&IF(IF($A$24=B35,"R1-S1 (Rak1 kiri), ","")&IF($B$24=B35,"R1-S2 (Rak1 tengah), ","")&IF($C$24=B35,"R1-S3 (Rak1 kanan), ","")&IF($D$24=B35,"R2-S1 (Rak2 kiri), ","")&IF($E$24=B35,"R2-S2 (Rak2 tengah), ","")&IF($F$24=B35,"R2-S3 (Rak2 kanan), ","")&IF($G$24=B35,"R3-S1 (Rak3 kiri), ","")&IF($H$24=B35,"R3-S2 (Rak3 tengah), ","")&IF($I$24=B35,"R3-S3 (Rak3 kanan), ","")="","",IF(LEN(IF($A$24=B35,"R1-S1 (Rak1 kiri), ","")&IF($B$24=B35,"R1-S2 (Rak1 tengah), ","")&IF($C$24=B35,"R1-S3 (Rak1 kanan), ","")&IF($D$24=B35,"R2-S1 (Rak2 kiri), ","")&IF($E$24=B35,"R2-S2 (Rak2 tengah), ","")&IF($F$24=B35,"R2-S3 (Rak2 kanan), ","")&IF($G$24=B35,"R3-S1 (Rak3 kiri), ","")&IF($H$24=B35,"R3-S2 (Rak3 tengah), ","")&IF($I$24=B35,"R3-S3 (Rak3 kanan), ",""))>2,LEFT(IF($A$24=B35,"R1-S1 (Rak1 kiri), ","")&IF($B$24=B35,"R1-S2 (Rak1 tengah), ","")&IF($C$24=B35,"R1-S3 (Rak1 kanan), ","")&IF($D$24=B35,"R2-S1 (Rak2 kiri), ","")&IF($E$24=B35,"R2-S2 (Rak2 tengah), ","")&IF($F$24=B35,"R2-S3 (Rak2 kanan), ","")&IF($G$24=B35,"R3-S1 (Rak3 kiri), ","")&IF($H$24=B35,"R3-S2 (Rak3 tengah), ","")&IF($I$24=B35,"R3-S3 (Rak3 kanan), ",""),LEN(IF($A$24=B35,"R1-S1 (Rak1 kiri), ","")&IF($B$24=B35,"R1-S2 (Rak1 tengah), ","")&IF($C$24=B35,"R1-S3 (Rak1 kanan), ","")&IF($D$24=B35,"R2-S1 (Rak2 kiri), ","")&IF($E$24=B35,"R2-S2 (Rak2 tengah), ","")&IF($F$24=B35,"R2-S3 (Rak2 kanan), ","")&IF($G$24=B35,"R3-S1 (Rak3 kiri), ","")&IF($H$24=B35,"R3-S2 (Rak3 tengah), ","")&IF($I$24=B35,"R3-S3 (Rak3 kanan), ",""))-2),IF($A$24=B35,"R1-S1 (Rak1 kiri), ","")&IF($B$24=B35,"R1-S2 (Rak1 tengah), ","")&IF($C$24=B35,"R1-S3 (Rak1 kanan), ","")&IF($D$24=B35,"R2-S1 (Rak2 kiri), ","")&IF($E$24=B35,"R2-S2 (Rak2 tengah), ","")&IF($F$24=B35,"R2-S3 (Rak2 kanan), ","")&IF($G$24=B35,"R3-S1 (Rak3 kiri), ","")&IF($H$24=B35,"R3-S2 (Rak3 tengah), ","")&IF($I$24=B35,"R3-S3 (Rak3 kanan), ","")))))) | J35: =IF(G35="","",IF(G35=1,0,1))
